go/tests/test_20240229113625.in
50
0-49 o
0 B 1 GOOGL 1234 30
0 S 2 NFLX 2345 1
0 C 1
0 S 3 INTC 1357 25
0 B 4 AAPL 2469 10
0 C 2
1 B 5 TSLA 1234 30
1 S 6 AMZN 2345 1
1 C 5
1 S 7 NVDA 1357 25
1 B 8 AMD 2469 10
1 C 6
2 B 9 TSLA 1234 30
2 S 10 AMZN 2345 1
2 C 9
2 S 11 AMD 1357 25
2 B 12 INTC 2469 10
2 C 10
3 B 13 AAPL 1234 30
3 S 14 NFLX 2345 1
3 C 13
3 S 15 GOOGL 1357 25
3 B 16 MSFT 2469 10
3 C 14
4 B 17 AMZN 1234 30
4 S 18 AMD 2345 1
4 C 17
4 S 19 NVDA 1357 25
4 B 20 TSLA 2469 10
4 C 18
5 B 21 NVDA 1234 30
5 S 22 NFLX 2345 1
5 C 21
5 S 23 NFLX 1357 25
5 B 24 MSFT 2469 10
5 C 22
6 B 25 AMD 1234 30
6 S 26 GOOGL 2345 1
6 C 25
6 S 27 INTC 1357 25
6 B 28 NFLX 2469 10
6 C 26
7 B 29 TSLA 1234 30
7 S 30 AMZN 2345 1
7 C 29
7 S 31 AAPL 1357 25
7 B 32 MSFT 2469 10
7 C 30
8 B 33 INTC 1234 30
8 S 34 AAPL 2345 1
8 C 33
8 S 35 AAPL 1357 25
8 B 36 NFLX 2469 10
8 C 34
9 B 37 AMD 1234 30
9 S 38 INTC 2345 1
9 C 37
9 S 39 AMD 1357 25
9 B 40 MSFT 2469 10
9 C 38
10 B 41 AMD 1234 30
10 S 42 MSFT 2345 1
10 C 41
10 S 43 AMD 1357 25
10 B 44 GOOGL 2469 10
10 C 42
11 B 45 GOOGL 1234 30
11 S 46 AMZN 2345 1
11 C 45
11 S 47 AMZN 1357 25
11 B 48 INTC 2469 10
11 C 46
12 B 49 INTC 1234 30
12 S 50 NFLX 2345 1
12 C 49
12 S 51 AMD 1357 25
12 B 52 NVDA 2469 10
12 C 50
13 B 53 GOOGL 1234 30
13 S 54 GOOGL 2345 1
13 C 53
13 S 55 INTC 1357 25
13 B 56 AMD 2469 10
13 C 54
14 B 57 INTC 1234 30
14 S 58 MSFT 2345 1
14 C 57
14 S 59 AAPL 1357 25
14 B 60 AAPL 2469 10
14 C 58
15 B 61 AMD 1234 30
15 S 62 INTC 2345 1
15 C 61
15 S 63 NVDA 1357 25
15 B 64 INTC 2469 10
15 C 62
16 B 65 AMD 1234 30
16 S 66 NFLX 2345 1
16 C 65
16 S 67 MSFT 1357 25
16 B 68 META 2469 10
16 C 66
17 B 69 META 1234 30
17 S 70 NVDA 2345 1
17 C 69
17 S 71 GOOGL 1357 25
17 B 72 AMZN 2469 10
17 C 70
18 B 73 INTC 1234 30
18 S 74 NVDA 2345 1
18 C 73
18 S 75 NVDA 1357 25
18 B 76 META 2469 10
18 C 74
19 B 77 INTC 1234 30
19 S 78 MSFT 2345 1
19 C 77
19 S 79 NVDA 1357 25
19 B 80 MSFT 2469 10
19 C 78
20 B 81 TSLA 1234 30
20 S 82 AMZN 2345 1
20 C 81
20 S 83 INTC 1357 25
20 B 84 AAPL 2469 10
20 C 82
21 B 85 MSFT 1234 30
21 S 86 NVDA 2345 1
21 C 85
21 S 87 META 1357 25
21 B 88 MSFT 2469 10
21 C 86
22 B 89 META 1234 30
22 S 90 TSLA 2345 1
22 C 89
22 S 91 INTC 1357 25
22 B 92 MSFT 2469 10
22 C 90
23 B 93 MSFT 1234 30
23 S 94 INTC 2345 1
23 C 93
23 S 95 INTC 1357 25
23 B 96 AAPL 2469 10
23 C 94
24 B 97 NVDA 1234 30
24 S 98 NFLX 2345 1
24 C 97
24 S 99 NVDA 1357 25
24 B 100 NVDA 2469 10
24 C 98
25 B 101 TSLA 1234 30
25 S 102 META 2345 1
25 C 101
25 S 103 META 1357 25
25 B 104 AAPL 2469 10
25 C 102
26 B 105 AMZN 1234 30
26 S 106 INTC 2345 1
26 C 105
26 S 107 AMZN 1357 25
26 B 108 MSFT 2469 10
26 C 106
27 B 109 AMZN 1234 30
27 S 110 GOOGL 2345 1
27 C 109
27 S 111 TSLA 1357 25
27 B 112 MSFT 2469 10
27 C 110
28 B 113 META 1234 30
28 S 114 AMD 2345 1
28 C 113
28 S 115 INTC 1357 25
28 B 116 MSFT 2469 10
28 C 114
29 B 117 INTC 1234 30
29 S 118 AMZN 2345 1
29 C 117
29 S 119 MSFT 1357 25
29 B 120 AMZN 2469 10
29 C 118
30 B 121 AMZN 1234 30
30 S 122 AAPL 2345 1
30 C 121
30 S 123 NFLX 1357 25
30 B 124 NFLX 2469 10
30 C 122
31 B 125 MSFT 1234 30
31 S 126 NVDA 2345 1
31 C 125
31 S 127 GOOGL 1357 25
31 B 128 GOOGL 2469 10
31 C 126
32 B 129 META 1234 30
32 S 130 META 2345 1
32 C 129
32 S 131 NVDA 1357 25
32 B 132 TSLA 2469 10
32 C 130
33 B 133 NFLX 1234 30
33 S 134 AMZN 2345 1
33 C 133
33 S 135 INTC 1357 25
33 B 136 NFLX 2469 10
33 C 134
34 B 137 INTC 1234 30
34 S 138 NVDA 2345 1
34 C 137
34 S 139 TSLA 1357 25
34 B 140 AMZN 2469 10
34 C 138
35 B 141 MSFT 1234 30
35 S 142 AAPL 2345 1
35 C 141
35 S 143 NFLX 1357 25
35 B 144 GOOGL 2469 10
35 C 142
36 B 145 TSLA 1234 30
36 S 146 TSLA 2345 1
36 C 145
36 S 147 NVDA 1357 25
36 B 148 META 2469 10
36 C 146
37 B 149 META 1234 30
37 S 150 TSLA 2345 1
37 C 149
37 S 151 MSFT 1357 25
37 B 152 AAPL 2469 10
37 C 150
38 B 153 AMD 1234 30
38 S 154 NVDA 2345 1
38 C 153
38 S 155 GOOGL 1357 25
38 B 156 TSLA 2469 10
38 C 154
39 B 157 GOOGL 1234 30
39 S 158 TSLA 2345 1
39 C 157
39 S 159 AMZN 1357 25
39 B 160 NVDA 2469 10
39 C 158
40 B 161 AMD 1234 30
40 S 162 AMD 2345 1
40 C 161
40 S 163 NFLX 1357 25
40 B 164 NVDA 2469 10
40 C 162
41 B 165 NFLX 1234 30
41 S 166 INTC 2345 1
41 C 165
41 S 167 TSLA 1357 25
41 B 168 NFLX 2469 10
41 C 166
42 B 169 GOOGL 1234 30
42 S 170 NFLX 2345 1
42 C 169
42 S 171 META 1357 25
42 B 172 GOOGL 2469 10
42 C 170
43 B 173 MSFT 1234 30
43 S 174 META 2345 1
43 C 173
43 S 175 NFLX 1357 25
43 B 176 INTC 2469 10
43 C 174
44 B 177 AMD 1234 30
44 S 178 TSLA 2345 1
44 C 177
44 S 179 AMZN 1357 25
44 B 180 AMD 2469 10
44 C 178
45 B 181 TSLA 1234 30
45 S 182 TSLA 2345 1
45 C 181
45 S 183 NVDA 1357 25
45 B 184 NFLX 2469 10
45 C 182
46 B 185 AMD 1234 30
46 S 186 NVDA 2345 1
46 C 185
46 S 187 AMD 1357 25
46 B 188 TSLA 2469 10
46 C 186
47 B 189 AMD 1234 30
47 S 190 TSLA 2345 1
47 C 189
47 S 191 INTC 1357 25
47 B 192 META 2469 10
47 C 190
48 B 193 MSFT 1234 30
48 S 194 AMD 2345 1
48 C 193
48 S 195 MSFT 1357 25
48 B 196 TSLA 2469 10
48 C 194
49 B 197 META 1234 30
49 S 198 MSFT 2345 1
49 C 197
49 S 199 AAPL 1357 25
49 B 200 TSLA 2469 10
49 C 198
.
0-49 x
