go/tests/test_20240229170541.in
100
0-99 o
0 B 1 NFLX 1234 30
0 S 2 NFLX 2345 1
0 C 1
0 S 3 TSLA 1357 25
0 B 4 MSFT 2469 10
0 C 2
1 B 5 AAPL 1234 30
1 S 6 AAPL 2345 1
1 C 5
1 S 7 TSLA 1357 25
1 B 8 AAPL 2469 10
1 C 6
2 B 9 GOOGL 1234 30
2 S 10 AMZN 2345 1
2 C 9
2 S 11 AMZN 1357 25
2 B 12 GOOGL 2469 10
2 C 10
3 B 13 NVDA 1234 30
3 S 14 NVDA 2345 1
3 C 13
3 S 15 INTC 1357 25
3 B 16 AMD 2469 10
3 C 14
4 B 17 AAPL 1234 30
4 S 18 AMZN 2345 1
4 C 17
4 S 19 AMZN 1357 25
4 B 20 TSLA 2469 10
4 C 18
5 B 21 AMD 1234 30
5 S 22 META 2345 1
5 C 21
5 S 23 MSFT 1357 25
5 B 24 INTC 2469 10
5 C 22
6 B 25 META 1234 30
6 S 26 AMZN 2345 1
6 C 25
6 S 27 META 1357 25
6 B 28 MSFT 2469 10
6 C 26
7 B 29 INTC 1234 30
7 S 30 AAPL 2345 1
7 C 29
7 S 31 INTC 1357 25
7 B 32 TSLA 2469 10
7 C 30
8 B 33 AMZN 1234 30
8 S 34 NFLX 2345 1
8 C 33
8 S 35 INTC 1357 25
8 B 36 MSFT 2469 10
8 C 34
9 B 37 GOOGL 1234 30
9 S 38 AMD 2345 1
9 C 37
9 S 39 INTC 1357 25
9 B 40 GOOGL 2469 10
9 C 38
10 B 41 META 1234 30
10 S 42 AMZN 2345 1
10 C 41
10 S 43 META 1357 25
10 B 44 INTC 2469 10
10 C 42
11 B 45 GOOGL 1234 30
11 S 46 AMD 2345 1
11 C 45
11 S 47 AAPL 1357 25
11 B 48 META 2469 10
11 C 46
12 B 49 MSFT 1234 30
12 S 50 AAPL 2345 1
12 C 49
12 S 51 GOOGL 1357 25
12 B 52 NFLX 2469 10
12 C 50
13 B 53 META 1234 30
13 S 54 TSLA 2345 1
13 C 53
13 S 55 GOOGL 1357 25
13 B 56 AMD 2469 10
13 C 54
14 B 57 NVDA 1234 30
14 S 58 GOOGL 2345 1
14 C 57
14 S 59 GOOGL 1357 25
14 B 60 AAPL 2469 10
14 C 58
15 B 61 AMZN 1234 30
15 S 62 GOOGL 2345 1
15 C 61
15 S 63 NVDA 1357 25
15 B 64 NFLX 2469 10
15 C 62
16 B 65 AMD 1234 30
16 S 66 META 2345 1
16 C 65
16 S 67 AMD 1357 25
16 B 68 AAPL 2469 10
16 C 66
17 B 69 AMD 1234 30
17 S 70 INTC 2345 1
17 C 69
17 S 71 AAPL 1357 25
17 B 72 INTC 2469 10
17 C 70
18 B 73 AAPL 1234 30
18 S 74 AMZN 2345 1
18 C 73
18 S 75 AMD 1357 25
18 B 76 NVDA 2469 10
18 C 74
19 B 77 NVDA 1234 30
19 S 78 GOOGL 2345 1
19 C 77
19 S 79 AMZN 1357 25
19 B 80 MSFT 2469 10
19 C 78
20 B 81 AAPL 1234 30
20 S 82 MSFT 2345 1
20 C 81
20 S 83 INTC 1357 25
20 B 84 INTC 2469 10
20 C 82
21 B 85 GOOGL 1234 30
21 S 86 AMD 2345 1
21 C 85
21 S 87 AMD 1357 25
21 B 88 AMD 2469 10
21 C 86
22 B 89 AMD 1234 30
22 S 90 TSLA 2345 1
22 C 89
22 S 91 INTC 1357 25
22 B 92 MSFT 2469 10
22 C 90
23 B 93 META 1234 30
23 S 94 AMD 2345 1
23 C 93
23 S 95 TSLA 1357 25
23 B 96 META 2469 10
23 C 94
24 B 97 META 1234 30
24 S 98 AAPL 2345 1
24 C 97
24 S 99 META 1357 25
24 B 100 NVDA 2469 10
24 C 98
25 B 101 NVDA 1234 30
25 S 102 MSFT 2345 1
25 C 101
25 S 103 TSLA 1357 25
25 B 104 AMD 2469 10
25 C 102
26 B 105 GOOGL 1234 30
26 S 106 MSFT 2345 1
26 C 105
26 S 107 INTC 1357 25
26 B 108 AMZN 2469 10
26 C 106
27 B 109 NVDA 1234 30
27 S 110 AAPL 2345 1
27 C 109
27 S 111 META 1357 25
27 B 112 TSLA 2469 10
27 C 110
28 B 113 GOOGL 1234 30
28 S 114 AMZN 2345 1
28 C 113
28 S 115 TSLA 1357 25
28 B 116 MSFT 2469 10
28 C 114
29 B 117 TSLA 1234 30
29 S 118 META 2345 1
29 C 117
29 S 119 AAPL 1357 25
29 B 120 INTC 2469 10
29 C 118
30 B 121 GOOGL 1234 30
30 S 122 NFLX 2345 1
30 C 121
30 S 123 TSLA 1357 25
30 B 124 TSLA 2469 10
30 C 122
31 B 125 NFLX 1234 30
31 S 126 INTC 2345 1
31 C 125
31 S 127 AMD 1357 25
31 B 128 AMZN 2469 10
31 C 126
32 B 129 NVDA 1234 30
32 S 130 TSLA 2345 1
32 C 129
32 S 131 MSFT 1357 25
32 B 132 GOOGL 2469 10
32 C 130
33 B 133 MSFT 1234 30
33 S 134 TSLA 2345 1
33 C 133
33 S 135 META 1357 25
33 B 136 META 2469 10
33 C 134
34 B 137 AMZN 1234 30
34 S 138 AAPL 2345 1
34 C 137
34 S 139 MSFT 1357 25
34 B 140 AMZN 2469 10
34 C 138
35 B 141 AMD 1234 30
35 S 142 INTC 2345 1
35 C 141
35 S 143 NFLX 1357 25
35 B 144 AMZN 2469 10
35 C 142
36 B 145 AAPL 1234 30
36 S 146 META 2345 1
36 C 145
36 S 147 NVDA 1357 25
36 B 148 INTC 2469 10
36 C 146
37 B 149 META 1234 30
37 S 150 AAPL 2345 1
37 C 149
37 S 151 GOOGL 1357 25
37 B 152 MSFT 2469 10
37 C 150
38 B 153 TSLA 1234 30
38 S 154 MSFT 2345 1
38 C 153
38 S 155 MSFT 1357 25
38 B 156 AMD 2469 10
38 C 154
39 B 157 MSFT 1234 30
39 S 158 AMZN 2345 1
39 C 157
39 S 159 META 1357 25
39 B 160 NFLX 2469 10
39 C 158
40 B 161 TSLA 1234 30
40 S 162 MSFT 2345 1
40 C 161
40 S 163 AMD 1357 25
40 B 164 AAPL 2469 10
40 C 162
41 B 165 MSFT 1234 30
41 S 166 NFLX 2345 1
41 C 165
41 S 167 NVDA 1357 25
41 B 168 NVDA 2469 10
41 C 166
42 B 169 MSFT 1234 30
42 S 170 AMZN 2345 1
42 C 169
42 S 171 AMZN 1357 25
42 B 172 INTC 2469 10
42 C 170
43 B 173 TSLA 1234 30
43 S 174 NVDA 2345 1
43 C 173
43 S 175 MSFT 1357 25
43 B 176 TSLA 2469 10
43 C 174
44 B 177 AAPL 1234 30
44 S 178 MSFT 2345 1
44 C 177
44 S 179 META 1357 25
44 B 180 NVDA 2469 10
44 C 178
45 B 181 AMZN 1234 30
45 S 182 MSFT 2345 1
45 C 181
45 S 183 AMZN 1357 25
45 B 184 META 2469 10
45 C 182
46 B 185 AMZN 1234 30
46 S 186 NVDA 2345 1
46 C 185
46 S 187 AAPL 1357 25
46 B 188 NFLX 2469 10
46 C 186
47 B 189 MSFT 1234 30
47 S 190 INTC 2345 1
47 C 189
47 S 191 NFLX 1357 25
47 B 192 GOOGL 2469 10
47 C 190
48 B 193 AMD 1234 30
48 S 194 NVDA 2345 1
48 C 193
48 S 195 AAPL 1357 25
48 B 196 NFLX 2469 10
48 C 194
49 B 197 NFLX 1234 30
49 S 198 TSLA 2345 1
49 C 197
49 S 199 AAPL 1357 25
49 B 200 TSLA 2469 10
49 C 198
50 B 201 NVDA 1234 30
50 S 202 AAPL 2345 1
50 C 201
50 S 203 AMZN 1357 25
50 B 204 META 2469 10
50 C 202
51 B 205 AMD 1234 30
51 S 206 TSLA 2345 1
51 C 205
51 S 207 MSFT 1357 25
51 B 208 TSLA 2469 10
51 C 206
52 B 209 MSFT 1234 30
52 S 210 NVDA 2345 1
52 C 209
52 S 211 META 1357 25
52 B 212 AAPL 2469 10
52 C 210
53 B 213 GOOGL 1234 30
53 S 214 MSFT 2345 1
53 C 213
53 S 215 META 1357 25
53 B 216 AMZN 2469 10
53 C 214
54 B 217 TSLA 1234 30
54 S 218 AMZN 2345 1
54 C 217
54 S 219 AMD 1357 25
54 B 220 AMZN 2469 10
54 C 218
55 B 221 INTC 1234 30
55 S 222 META 2345 1
55 C 221
55 S 223 NFLX 1357 25
55 B 224 AMZN 2469 10
55 C 222
56 B 225 GOOGL 1234 30
56 S 226 GOOGL 2345 1
56 C 225
56 S 227 META 1357 25
56 B 228 AAPL 2469 10
56 C 226
57 B 229 INTC 1234 30
57 S 230 AAPL 2345 1
57 C 229
57 S 231 AAPL 1357 25
57 B 232 AAPL 2469 10
57 C 230
58 B 233 AMZN 1234 30
58 S 234 AAPL 2345 1
58 C 233
58 S 235 NVDA 1357 25
58 B 236 MSFT 2469 10
58 C 234
59 B 237 META 1234 30
59 S 238 TSLA 2345 1
59 C 237
59 S 239 AMD 1357 25
59 B 240 MSFT 2469 10
59 C 238
60 B 241 INTC 1234 30
60 S 242 TSLA 2345 1
60 C 241
60 S 243 MSFT 1357 25
60 B 244 MSFT 2469 10
60 C 242
61 B 245 META 1234 30
61 S 246 GOOGL 2345 1
61 C 245
61 S 247 MSFT 1357 25
61 B 248 INTC 2469 10
61 C 246
62 B 249 TSLA 1234 30
62 S 250 NVDA 2345 1
62 C 249
62 S 251 AMZN 1357 25
62 B 252 MSFT 2469 10
62 C 250
63 B 253 AAPL 1234 30
63 S 254 GOOGL 2345 1
63 C 253
63 S 255 AAPL 1357 25
63 B 256 MSFT 2469 10
63 C 254
64 B 257 MSFT 1234 30
64 S 258 TSLA 2345 1
64 C 257
64 S 259 INTC 1357 25
64 B 260 NFLX 2469 10
64 C 258
65 B 261 GOOGL 1234 30
65 S 262 TSLA 2345 1
65 C 261
65 S 263 AMD 1357 25
65 B 264 AMZN 2469 10
65 C 262
66 B 265 AAPL 1234 30
66 S 266 MSFT 2345 1
66 C 265
66 S 267 AAPL 1357 25
66 B 268 INTC 2469 10
66 C 266
67 B 269 NFLX 1234 30
67 S 270 NVDA 2345 1
67 C 269
67 S 271 AMZN 1357 25
67 B 272 AMD 2469 10
67 C 270
68 B 273 AAPL 1234 30
68 S 274 AAPL 2345 1
68 C 273
68 S 275 AAPL 1357 25
68 B 276 MSFT 2469 10
68 C 274
69 B 277 NFLX 1234 30
69 S 278 TSLA 2345 1
69 C 277
69 S 279 NFLX 1357 25
69 B 280 NVDA 2469 10
69 C 278
70 B 281 AMD 1234 30
70 S 282 NFLX 2345 1
70 C 281
70 S 283 AMZN 1357 25
70 B 284 TSLA 2469 10
70 C 282
71 B 285 AMZN 1234 30
71 S 286 AMZN 2345 1
71 C 285
71 S 287 META 1357 25
71 B 288 NVDA 2469 10
71 C 286
72 B 289 NFLX 1234 30
72 S 290 MSFT 2345 1
72 C 289
72 S 291 GOOGL 1357 25
72 B 292 AMZN 2469 10
72 C 290
73 B 293 GOOGL 1234 30
73 S 294 AAPL 2345 1
73 C 293
73 S 295 MSFT 1357 25
73 B 296 META 2469 10
73 C 294
74 B 297 AMD 1234 30
74 S 298 META 2345 1
74 C 297
74 S 299 MSFT 1357 25
74 B 300 META 2469 10
74 C 298
75 B 301 NVDA 1234 30
75 S 302 META 2345 1
75 C 301
75 S 303 AMD 1357 25
75 B 304 TSLA 2469 10
75 C 302
76 B 305 AMZN 1234 30
76 S 306 TSLA 2345 1
76 C 305
76 S 307 MSFT 1357 25
76 B 308 AAPL 2469 10
76 C 306
77 B 309 AMD 1234 30
77 S 310 TSLA 2345 1
77 C 309
77 S 311 GOOGL 1357 25
77 B 312 NVDA 2469 10
77 C 310
78 B 313 INTC 1234 30
78 S 314 MSFT 2345 1
